<?xml version="1.0" encoding="UTF-8"?>
<testng-results skipped="2" failed="2" ignored="0" total="8" passed="4">
  <reporter-output>
  </reporter-output>
  <suite name="Suite" duration-ms="133" started-at="2021-09-05T10:58:03Z" finished-at="2021-09-05T10:58:03Z">
    <groups>
    </groups>
    <test name="Test" duration-ms="133" started-at="2021-09-05T10:58:03Z" finished-at="2021-09-05T10:58:03Z">
      <class name="sample.DemoTest02">
        <test-method status="PASS" signature="testCase_005()[pri:0, instance:sample.DemoTest02@59fa1d9b]" name="testCase_005" duration-ms="0" started-at="2021-09-05T16:28:03Z" finished-at="2021-09-05T16:28:03Z">
          <reporter-output>
          </reporter-output>
        </test-method> <!-- testCase_005 -->
        <test-method status="PASS" signature="testCase_006()[pri:0, instance:sample.DemoTest02@59fa1d9b]" name="testCase_006" duration-ms="0" started-at="2021-09-05T16:28:03Z" finished-at="2021-09-05T16:28:03Z">
          <reporter-output>
          </reporter-output>
        </test-method> <!-- testCase_006 -->
        <test-method status="FAIL" signature="testCase_007()[pri:0, instance:sample.DemoTest02@59fa1d9b]" name="testCase_007" duration-ms="0" started-at="2021-09-05T16:28:03Z" finished-at="2021-09-05T16:28:03Z">
          <exception class="java.lang.AssertionError">
            <message>
              <![CDATA[expected [true] but found [false]]]>
            </message>
            <full-stacktrace>
              <![CDATA[java.lang.AssertionError: expected [true] but found [false]
	at org.testng.Assert.fail(Assert.java:94)
	at org.testng.Assert.failNotEquals(Assert.java:513)
	at org.testng.Assert.assertTrue(Assert.java:42)
	at org.testng.Assert.assertTrue(Assert.java:52)
	at sample.DemoTest02.testCase_007(DemoTest02.java:28)
	at sun.reflect.NativeMethodAccessorImpl.invoke0(Native Method)
	at sun.reflect.NativeMethodAccessorImpl.invoke(NativeMethodAccessorImpl.java:62)
	at sun.reflect.DelegatingMethodAccessorImpl.invoke(DelegatingMethodAccessorImpl.java:43)
	at java.lang.reflect.Method.invoke(Method.java:498)
	at org.testng.internal.MethodInvocationHelper.invokeMethod(MethodInvocationHelper.java:104)
	at org.testng.internal.Invoker.invokeMethod(Invoker.java:645)
	at org.testng.internal.Invoker.invokeTestMethod(Invoker.java:851)
	at org.testng.internal.Invoker.invokeTestMethods(Invoker.java:1177)
	at org.testng.internal.TestMethodWorker.invokeTestMethods(TestMethodWorker.java:129)
	at org.testng.internal.TestMethodWorker.run(TestMethodWorker.java:112)
	at org.testng.TestRunner.privateRun(TestRunner.java:756)
	at org.testng.TestRunner.run(TestRunner.java:610)
	at org.testng.SuiteRunner.runTest(SuiteRunner.java:387)
	at org.testng.SuiteRunner.runSequentially(SuiteRunner.java:382)
	at org.testng.SuiteRunner.privateRun(SuiteRunner.java:340)
	at org.testng.SuiteRunner.run(SuiteRunner.java:289)
	at org.testng.SuiteRunnerWorker.runSuite(SuiteRunnerWorker.java:52)
	at org.testng.SuiteRunnerWorker.run(SuiteRunnerWorker.java:86)
	at org.testng.TestNG.runSuitesSequentially(TestNG.java:1293)
	at org.testng.TestNG.runSuitesLocally(TestNG.java:1218)
	at org.testng.TestNG.runSuites(TestNG.java:1133)
	at org.testng.TestNG.run(TestNG.java:1104)
	at org.testng.remote.AbstractRemoteTestNG.run(AbstractRemoteTestNG.java:132)
	at org.testng.remote.RemoteTestNG.initAndRun(RemoteTestNG.java:236)
	at org.testng.remote.RemoteTestNG.main(RemoteTestNG.java:81)
]]>
            </full-stacktrace>
          </exception> <!-- java.lang.AssertionError -->
          <reporter-output>
          </reporter-output>
        </test-method> <!-- testCase_007 -->
        <test-method status="SKIP" signature="testCase_008()[pri:0, instance:sample.DemoTest02@59fa1d9b]" name="testCase_008" duration-ms="0" started-at="2021-09-05T16:28:03Z" depends-on-methods="sample.DemoTest02.testCase_007" finished-at="2021-09-05T16:28:03Z">
          <exception class="java.lang.Throwable">
            <message>
              <![CDATA[Method DemoTest02.testCase_008()[pri:0, instance:sample.DemoTest02@59fa1d9b] depends on not successfully finished methods]]>
            </message>
            <full-stacktrace>
              <![CDATA[java.lang.Throwable: Method DemoTest02.testCase_008()[pri:0, instance:sample.DemoTest02@59fa1d9b] depends on not successfully finished methods
	at org.testng.internal.Invoker.invokeTestMethods(Invoker.java:1068)
	at org.testng.internal.TestMethodWorker.invokeTestMethods(TestMethodWorker.java:129)
	at org.testng.internal.TestMethodWorker.run(TestMethodWorker.java:112)
	at org.testng.TestRunner.privateRun(TestRunner.java:756)
	at org.testng.TestRunner.run(TestRunner.java:610)
	at org.testng.SuiteRunner.runTest(SuiteRunner.java:387)
	at org.testng.SuiteRunner.runSequentially(SuiteRunner.java:382)
	at org.testng.SuiteRunner.privateRun(SuiteRunner.java:340)
	at org.testng.SuiteRunner.run(SuiteRunner.java:289)
	at org.testng.SuiteRunnerWorker.runSuite(SuiteRunnerWorker.java:52)
	at org.testng.SuiteRunnerWorker.run(SuiteRunnerWorker.java:86)
	at org.testng.TestNG.runSuitesSequentially(TestNG.java:1293)
	at org.testng.TestNG.runSuitesLocally(TestNG.java:1218)
	at org.testng.TestNG.runSuites(TestNG.java:1133)
	at org.testng.TestNG.run(TestNG.java:1104)
	at org.testng.remote.AbstractRemoteTestNG.run(AbstractRemoteTestNG.java:132)
	at org.testng.remote.RemoteTestNG.initAndRun(RemoteTestNG.java:236)
	at org.testng.remote.RemoteTestNG.main(RemoteTestNG.java:81)
]]>
            </full-stacktrace>
          </exception> <!-- java.lang.Throwable -->
          <reporter-output>
          </reporter-output>
        </test-method> <!-- testCase_008 -->
      </class> <!-- sample.DemoTest02 -->
      <class name="sample.DemoTest01">
        <test-method status="FAIL" signature="testCase_003()[pri:0, instance:sample.DemoTest01@14acaea5]" name="testCase_003" duration-ms="32" started-at="2021-09-05T16:28:03Z" finished-at="2021-09-05T16:28:03Z">
          <exception class="java.lang.AssertionError">
            <message>
              <![CDATA[expected [true] but found [false]]]>
            </message>
            <full-stacktrace>
              <![CDATA[java.lang.AssertionError: expected [true] but found [false]
	at org.testng.Assert.fail(Assert.java:94)
	at org.testng.Assert.failNotEquals(Assert.java:513)
	at org.testng.Assert.assertTrue(Assert.java:42)
	at org.testng.Assert.assertTrue(Assert.java:52)
	at sample.DemoTest01.testCase_003(DemoTest01.java:28)
	at sun.reflect.NativeMethodAccessorImpl.invoke0(Native Method)
	at sun.reflect.NativeMethodAccessorImpl.invoke(NativeMethodAccessorImpl.java:62)
	at sun.reflect.DelegatingMethodAccessorImpl.invoke(DelegatingMethodAccessorImpl.java:43)
	at java.lang.reflect.Method.invoke(Method.java:498)
	at org.testng.internal.MethodInvocationHelper.invokeMethod(MethodInvocationHelper.java:104)
	at org.testng.internal.Invoker.invokeMethod(Invoker.java:645)
	at org.testng.internal.Invoker.invokeTestMethod(Invoker.java:851)
	at org.testng.internal.Invoker.invokeTestMethods(Invoker.java:1177)
	at org.testng.internal.TestMethodWorker.invokeTestMethods(TestMethodWorker.java:129)
	at org.testng.internal.TestMethodWorker.run(TestMethodWorker.java:112)
	at org.testng.TestRunner.privateRun(TestRunner.java:756)
	at org.testng.TestRunner.run(TestRunner.java:610)
	at org.testng.SuiteRunner.runTest(SuiteRunner.java:387)
	at org.testng.SuiteRunner.runSequentially(SuiteRunner.java:382)
	at org.testng.SuiteRunner.privateRun(SuiteRunner.java:340)
	at org.testng.SuiteRunner.run(SuiteRunner.java:289)
	at org.testng.SuiteRunnerWorker.runSuite(SuiteRunnerWorker.java:52)
	at org.testng.SuiteRunnerWorker.run(SuiteRunnerWorker.java:86)
	at org.testng.TestNG.runSuitesSequentially(TestNG.java:1293)
	at org.testng.TestNG.runSuitesLocally(TestNG.java:1218)
	at org.testng.TestNG.runSuites(TestNG.java:1133)
	at org.testng.TestNG.run(TestNG.java:1104)
	at org.testng.remote.AbstractRemoteTestNG.run(AbstractRemoteTestNG.java:132)
	at org.testng.remote.RemoteTestNG.initAndRun(RemoteTestNG.java:236)
	at org.testng.remote.RemoteTestNG.main(RemoteTestNG.java:81)
]]>
            </full-stacktrace>
          </exception> <!-- java.lang.AssertionError -->
          <reporter-output>
          </reporter-output>
        </test-method> <!-- testCase_003 -->
        <test-method status="PASS" signature="testCase_001()[pri:0, instance:sample.DemoTest01@14acaea5]" name="testCase_001" duration-ms="5" started-at="2021-09-05T16:28:03Z" finished-at="2021-09-05T16:28:03Z">
          <reporter-output>
          </reporter-output>
        </test-method> <!-- testCase_001 -->
        <test-method status="PASS" signature="testCase_002()[pri:0, instance:sample.DemoTest01@14acaea5]" name="testCase_002" duration-ms="5" started-at="2021-09-05T16:28:03Z" finished-at="2021-09-05T16:28:03Z">
          <reporter-output>
          </reporter-output>
        </test-method> <!-- testCase_002 -->
        <test-method status="SKIP" signature="testCase_004()[pri:0, instance:sample.DemoTest01@14acaea5]" name="testCase_004" duration-ms="0" started-at="2021-09-05T16:28:03Z" depends-on-methods="sample.DemoTest01.testCase_003" finished-at="2021-09-05T16:28:03Z">
          <exception class="java.lang.Throwable">
            <message>
              <![CDATA[Method DemoTest01.testCase_004()[pri:0, instance:sample.DemoTest01@14acaea5] depends on not successfully finished methods]]>
            </message>
            <full-stacktrace>
              <![CDATA[java.lang.Throwable: Method DemoTest01.testCase_004()[pri:0, instance:sample.DemoTest01@14acaea5] depends on not successfully finished methods
	at org.testng.internal.Invoker.invokeTestMethods(Invoker.java:1068)
	at org.testng.internal.TestMethodWorker.invokeTestMethods(TestMethodWorker.java:129)
	at org.testng.internal.TestMethodWorker.run(TestMethodWorker.java:112)
	at org.testng.TestRunner.privateRun(TestRunner.java:756)
	at org.testng.TestRunner.run(TestRunner.java:610)
	at org.testng.SuiteRunner.runTest(SuiteRunner.java:387)
	at org.testng.SuiteRunner.runSequentially(SuiteRunner.java:382)
	at org.testng.SuiteRunner.privateRun(SuiteRunner.java:340)
	at org.testng.SuiteRunner.run(SuiteRunner.java:289)
	at org.testng.SuiteRunnerWorker.runSuite(SuiteRunnerWorker.java:52)
	at org.testng.SuiteRunnerWorker.run(SuiteRunnerWorker.java:86)
	at org.testng.TestNG.runSuitesSequentially(TestNG.java:1293)
	at org.testng.TestNG.runSuitesLocally(TestNG.java:1218)
	at org.testng.TestNG.runSuites(TestNG.java:1133)
	at org.testng.TestNG.run(TestNG.java:1104)
	at org.testng.remote.AbstractRemoteTestNG.run(AbstractRemoteTestNG.java:132)
	at org.testng.remote.RemoteTestNG.initAndRun(RemoteTestNG.java:236)
	at org.testng.remote.RemoteTestNG.main(RemoteTestNG.java:81)
]]>
            </full-stacktrace>
          </exception> <!-- java.lang.Throwable -->
          <reporter-output>
          </reporter-output>
        </test-method> <!-- testCase_004 -->
      </class> <!-- sample.DemoTest01 -->
    </test> <!-- Test -->
  </suite> <!-- Suite -->
</testng-results>
